Workbook

Sheet Identification
A1: No enregistrement | B1: Societe | C1: Pays | D1: Branche | E1: Directeur general | F1: Date de creation | G1: Capital social (F CFA) | H1: Cadres | I1: Maitrise | J1: Employes | K1: Annee N
A2: 1 | B2: ATLANTIQUE ASSURANCE BENIN VIE | C2: BENIN | D2: Vie | E2: Corinne GBENOU FOURN | F2: 34662 | G2: 3299350000 | H2: 9 | I2: 6 | J2: 2 | K2: 2023
A3: 2 | B3: CIF ASSURANCES VIE | C3: BENIN | D3: Vie | E3: Félix Edouard LADEKAN | F3: 41261 | G3: 1249280000 | H3: 11 | I3: 2 | J3: 2 | K3: 2023
A4: 3 | B4: L'AFRICAINE VIE BENIN | C4: BENIN | D4: Vie | E4: Hervé TCHIAKPE | F4: 38821 | G4: 3000000000 | H4: 10 | I4: 17 | J4: 2 | K4: 2023
A5: 4 | B5: NOUVELLE SOCIETE INTERAFRICAINE D'ASSURANCES VIE | C5: BENIN | D5: Vie | E5: DOSSOU FREJUS LIDWIN | F5: 38457 | G5: 3000000000 | H5: 14 | I5: 9 | J5: 2 | K5: 2023
A6: 5 | B6: SANLAM ASSURANCE VIE | C6: BENIN | D6: Vie | E6: Mariam NASSIROU | F6: 35230 | G6: 3000000000 | H6: 16 | I6: 49 | J6: 0 | K6: 2023
A7: 6 | B7: SUNU ASSURANCES VIE BENIN | C7: BENIN | D7: Vie | E7: Souleymane Wassila FAYE | F7: 34655 | G7: 3000000000 | H7: 37 | I7: 6 | J7: 1 | K7: 2023
A8: 7 | B8: ATLANTIQUE ASSURANCES BENIN IARDT | C8: BENIN | D8: Non-vie | E8: AYIVI-ELEGBEDE Florence | F8: 42459 | G8: 5000000000 | H8: 21 | I8: 23 | J8: 4 | K8: 2023
A9: 8 | B9: L'AFRICAINE DES ASSURANCES | C9: BENIN | D9: Non-vie | E9: Kenneth ELEGBEDE | F9: 35739 | G9: 4493470000 | H9: 29 | I9: 48 | J9: 7 | K9: 2023
A10: 9 | B10: LA GENERALE DES ASSURANCES | C10: BENIN | D10: Non-vie | E10: Gaston Arnaud de SOUZA | F10: 36280 | G10: 3000000000 | H10: 7 | I10: 9 | J10: 9 | K10: 2023
A11: 10 | B11: NOBILA ASSURANCES SA | C11: BENIN | D11: Non-vie | E11: André A. AZIBLI | F11: 38630 | G11: 3000000000 | H11: 9 | I11: 8 | J11: 11 | K11: 2023
A12: 11 | B12: NOUVELLE SOCIETE INTERAFRICAINE D'ASSURANCES | C12: BENIN | D12: Non-vie | E12: AGBOTA Fabrice | F12: 35796 | G12: 4800000000 | H12: 27 | I12: 25 | J12: 4 | K12: 2023
A13: 12 | B13: SANLAM ASSURANCE | C13: BENIN | D13: Non-vie | E13: Edmond DOSSOU | F13: 40420 | G13: 3000000000 | H13: 12 | I13: 22 | J13: 2 | K13: 2023
... A48: 47 | B48: ALLIANZ CÔTE D'IVOIRE ASSURANCES | C48: COTE D'IVOIRE | D48: Non-vie | E48: Mamadou G. K. KONE | F48: 27760 | G48: 3000000000 | H48: 55 | I48: 49 | J48: 2 | K48: 2023
A49: 48 | B49: AMSA ASSURANCES | C49: COTE D'IVOIRE | D49: Non-vie | E49: Yatassaye SAMBA | F49: En 1972 | G49: 5000000000 | H49: 43 | I49: 49 | J49: 3 | K49: 2023
A50: 49 | B50: ASSURANCES COMAR Côte d’Ivoire (COMAR-CI) | C50: COTE D'IVOIRE | D50: Non-vie | E50: Théophile MBORO ASSOGHO | F50: 42681 | G50: 8747780000 | H50: 20 | I50: 23 | J50: 4 | K50: 2023
A51: 50 | B51: ATLANTIQUE ASSURANCES COTE D'IVOIRE (AACI) | C51: COTE D'IVOIRE | D51: Non-vie | E51: Estelle TRAORE | F51: 1956 | G51: 3000000000 | H51: 45 | I51: 29 | J51: 7 | K51: 2023
A52: 51 | B52: AXA ASSURANCES | C52: COTE D'IVOIRE | D52: Non-vie | E52: Téyi LAWSON | F52: 29587 | G52: 5000006000 | H52: 34 | I52: 30 | J52: 0 | K52: 2023
A53: 52 | B53: LA LOYALE ASSURANCES | C53: COTE D'IVOIRE | D53: Non-vie | E53: BROU Yvette Mamy Koko | F53: 37926 | G53: 3486932497 | H53: 16 | I53: 20 | J53: 11 | K53: 2023
A54: 53 | B54: NOUVELLE SOCIETE INTERAFRICAINE D'ASSURANCES | C54: COTE D'IVOIRE | D54: Non-vie | E54: Magloire DOCHAMOU | F54: 34851 | G54: 7600000000 | H54: 78 | I54: 39 | J54: 3 | K54: 2023
A55: 54 | B55: SANLAM ASSURANCE CÔTE D'IVOIRE | C55: COTE D'IVOIRE | D55: Non-vie | E55: OUEDRAOGO Roland Zwewendpaogre | F55: 29252 | G55: 5000000000 | H55: 68 | I55: 54 | J55: 29 | K55: 2023
A56: 55 | B56: SERENITY ASSURANCES SA | C56: COTE D'IVOIRE | D56: Non-vie | E56: Maurice KIPPRE DIGBEU | F56: 39554 | G56: 3000000000 | H56: 24 | I56: 60 | J56: 23 | K56: 2023
A57: 56 | B57: SONAM GENERALE ASSURANCES COTE D'IVOIRE | C57: COTE D'IVOIRE | D57: Non-vie | E57: Papa Ibra DIENA | F57: 1987 | G57: 500000000 | H57: 14 | I57: 37 | J57: 14 | K57: 2023
A58: 57 | B58: SUNU ASSURANCES IARD | C58: COTE D'IVOIRE | D58: Non-vie | E58: Mamadou Moussa DIOUF | F58: 35529 | G58: 5000000000 | H58: 39 | I58: 27 | J58: 0 | K58: 2023
A59: 58 | B59: ASSURANCES INDUSTRIELLES ET COMMERCIALES SA | C59: GABON | D59: Non-vie | E59: Stephen MOUSSIROU | F59: 35431 | G59: 6000000000 | H59: 33 | I59: 28 | J59: 11 | K59: 2023
A60: 59 | B60: AXA ASSURANCES | C60: GABON | D60: Non-vie | E60: Marielle BAYE | F60: 27760 | G60: 5022465000 | H60: 24 | I60: 32 | J60: 18 | K60: 2023
A61: 60 | B61: CIF ASSURANCES-VIE MALI | C61: MALI | D61: Vie | E61: Corneille SANON | F61: 43096 | G61: 1167340000 | H61: 7 | I61: 1 | J61: 1 | K61: 2023
A62: 61 | B62: NSIA VIE MALI | C62: MALI | D62: Vie | E62: Lamine COULIBALY | F62: 39961 | G62: 7745170000 | H62: 3 | I62: 18 | J62: 2 | K62: 2023
A63: 62 | B63: SANLAM ASSURANCE VIE MALI | C63: MALI | D63: Vie | E63: Bikiry MAKANGUILE | F63: 40716 | G63: 3000000000 | H63: 7 | I63: 9 | J63: 14 | K63: 2023
A64: 63 | B64: SOCIETE NOUVELLE D'ASSURANCE VIE (SONAVIE) | C64: MALI | D64: Vie | E64: Adama DIALLO | F64: 35247 | G64: 5158990000 | H64: 15 | I64: 0 | J64: 22 | K64: 2023
A65: 64 | B65: AFG ASSURANCES MALI IARD | C65: MALI | D65: Non-vie | E65: CISSE Adam BA | F65: 41997 | G65: 3000000000 | H65: 8 | I65: 23 | J65: 14 | K65: 2023
A66: 65 | B66: ASSURANCES LAFIA SA | C66: MALI | D66: Non-vie | E66: Kadiatou KONE | F66: 30523 | G66: 3000000000 | H66: 14 | I66: 5 | J66: 14 | K66: 2023
A67: 66 | B67: COMPAGNIE D'ASSURANCE ET REASSURANCE SABU NYUMAN | C67: MALI | D67: Non-vie | E67: Abdrahamane KOUYATE | F67: 30772 | G67: 4379560000 | H67: 5 | I67: 21 | J67: 18 | K67: 2023
A68: 67 | B68: LES ASSURANCES BLEUES CNAR | C68: MALI | D68: Non-vie | E68: SANOGO Karim | F68: 25239 | G68: 3383897675 | H68: 13 | I68: 11 | J68: 14 | K68: 2023
A69: 68 | B69: NOUVELLE ALLIANCE D'ASSURANCES SA | C69: MALI | D69: Non-vie | E69: Abdoulaye TOURE | F69: 39133 | G69: 3000000000 | H69: 2 | I69: 8 | J69: 9 | K69: 2023
... A86: 85 | B86: SAAR VIE SENEGAL | C86: SENEGAL | D86: Vie | E86: BOPDA FONKO Cyrille | F86: 34074 | G86: 5000000000 | H86: 6 | I86: 4 | J86: 0 | K86: 2023
A87: 86 | B87: SONAM ASSURANCES VIE | C87: SENEGAL | D87: Vie | E87: Souleymane NIANE | F87: 25/09/20212 | G87: 3000000000 | H87: 12 | I87: 17 | J87: 18 | K87: 2023
A88: 87 | B88: SUNU ASSURANCES VIE SENEGAL | C88: SENEGAL | D88: Vie | E88: SY Adjaratou Khady NDAO | F88: 31658 | G88: 3000000000 | H88: 6 | I88: 30 | J88: 0 | K88: 2023
A89: 88 | B89: WAFA ASSURANCE VIE | C89: SENEGAL | D89: Vie | E89: Chakib HASSAN | F89: 41894 | G89: 3000000000 | H89: 11 | I89: 19 | J89: 0 | K89: 2023
A90: 89 | B90: ALLIANZ SENEGAL ASSURANCES | C90: SENEGAL | D90: Non-vie | E90: Alphonsine DASILVA | F90: 32121 | G90: 3000000000 | H90: 29 | I90: 28 | J90: 4 | K90: 2023
...

Sheet Emission&Prestations
A1: No enregistrement | B1: Societe | C1: Pays | D1: Branche | E1: Bloc | F1: Categorie | G1: Rubrique | H1: Mesure | I1: Annee | J1: Valeur (F CFA)
A2: 1 | B2: ATLANTIQUE ASSURANCE BENIN VIE | C2: BENIN | D2: Vie | E2: Emissions | F2: Individuelles | G2: Contrats en cas de vie | H2: Emissions nettes | I2: 2022 | J2: =IF('Emission&Prestations (brut)'!J2="","",'Emission&Prestations (brut)'!J2*1000)
A3: 1 | B3: ATLANTIQUE ASSURANCE BENIN VIE | C3: BENIN | D3: Vie | E3: Emissions | F3: Individuelles | G3: Contrats en cas de vie | H3: Emissions nettes | I3: 2023 | J3: =IF('Emission&Prestations (brut)'!J3="","",'Emission&Prestations (brut)'!J3*1000)
A4: 1 | B4: ATLANTIQUE ASSURANCE BENIN VIE | C4: BENIN | D4: Vie | E4: Emissions | F4: Individuelles | G4: Contrat en cas de décès | H4: Emissions nettes | I4: 2022 | J4: =IF('Emission&Prestations (brut)'!J4="","",'Emission&Prestations (brut)'!J4*1000)
A5: 1 | B5: ATLANTIQUE ASSURANCE BENIN VIE | C5: BENIN | D5: Vie | E5: Emissions | F5: Individuelles | G5: Contrat en cas de décès | H5: Emissions nettes | I5: 2023 | J5: =IF('Emission&Prestations (brut)'!J5="","",'Emission&Prestations (brut)'!J5*1000)
A6: 1 | B6: ATLANTIQUE ASSURANCE BENIN VIE | C6: BENIN | D6: Vie | E6: Emissions | F6: Individuelles | G6: Mixte | H6: Emissions nettes | I6: 2022 | J6: =IF('Emission&Prestations (brut)'!J6="","",'Emission&Prestations (brut)'!J6*1000)
A7: 1 | B7: ATLANTIQUE ASSURANCE BENIN VIE | C7: BENIN | D7: Vie | E7: Emissions | F7: Individuelles | G7: Mixte | H7: Emissions nettes | I7: 2023 | J7: =IF('Emission&Prestations (brut)'!J7="","",'Emission&Prestations (brut)'!J7*1000)
A8: 1 | B8: ATLANTIQUE ASSURANCE BENIN VIE | C8: BENIN | D8: Vie | E8: Emissions | F8: Individuelles | G8: Epargne | H8: Emissions nettes | I8: 2022 | J8: =IF('Emission&Prestations (brut)'!J8="","",'Emission&Prestations (brut)'!J8*1000)
A9: 1 | B9: ATLANTIQUE ASSURANCE BENIN VIE | C9: BENIN | D9: Vie | E9: Emissions | F9: Individuelles | G9: Epargne | H9: Emissions nettes | I9: 2023 | J9: =IF('Emission&Prestations (brut)'!J9="","",'Emission&Prestations (brut)'!J9*1000)
A10: 1 | B10: ATLANTIQUE ASSURANCE BENIN VIE | C10: BENIN | D10: Vie | E10: Emissions | F10: Individuelles | G10: Titre de capitalisation | H10: Emissions nettes | I10: 2022 | J10: =IF('Emission&Prestations (brut)'!J10="","",'Emission&Prestations (brut)'!J10*1000)
A11: 1 | B11: ATLANTIQUE ASSURANCE BENIN VIE | C11: BENIN | D11: Vie | E11: Emissions | F11: Individuelles | G11: Titre de capitalisation | H11: Emissions nettes | I11: 2023 | J11: =IF('Emission&Prestations (brut)'!J11="","",'Emission&Prestations (brut)'!J11*1000)
A12: 1 | B12: ATLANTIQUE ASSURANCE BENIN VIE | C12: BENIN | D12: Vie | E12: Emissions | F12: Individuelles | G12: Complémentaires | H12: Emissions nettes | I12: 2022 | J12: =IF('Emission&Prestations (brut)'!J12="","",'Emission&Prestations (brut)'!J12*1000)
A13: 1 | B13: ATLANTIQUE ASSURANCE BENIN VIE | C13: BENIN | D13: Vie | E13: Emissions | F13: Individuelles | G13: Complémentaires | H13: Emissions nettes | I13: 2023 | J13: =IF('Emission&Prestations (brut)'!J13="","",'Emission&Prestations (brut)'!J13*1000)
... A6687: 117 | B6687: SUNU ASSURANCES IARD - TOGO | C6687: TOGO | D6687: Non-vie | E6687: Sinistralite | F6687: Acceptations | G6687: Acceptations | H6687: Charges de sinistres (CS) | I6687: 2023 | J6687: =IF('Emission&Prestations (brut)'!J6687="","",'Emission&Prestations (brut)'!J6687*1000)

Sheet Chiffres clés
A1: No enregistrement | B1: Societe | C1: Pays | D1: Branche | E1: Rubrique | F1: Annee | G1: Valeur (F CFA)
A2: 1 | B2: ATLANTIQUE ASSURANCE BENIN VIE | C2: BENIN | D2: Vie | E2: Produits financiers nets | F2: 2022 | G2: =IF('Chiffres clés (brut)'!G2="","",'Chiffres clés (brut)'!G2*1000)
A3: 1 | B3: ATLANTIQUE ASSURANCE BENIN VIE | C3: BENIN | D3: Vie | E3: Produits financiers nets | F3: 2023 | G3: =IF('Chiffres clés (brut)'!G3="","",'Chiffres clés (brut)'!G3*1000)
A4: 1 | B4: ATLANTIQUE ASSURANCE BENIN VIE | C4: BENIN | D4: Vie | E4: Commissions | F4: 2022 | G4: =IF('Chiffres clés (brut)'!G4="","",'Chiffres clés (brut)'!G4*1000)
A5: 1 | B5: ATLANTIQUE ASSURANCE BENIN VIE | C5: BENIN | D5: Vie | E5: Commissions | F5: 2023 | G5: =IF('Chiffres clés (brut)'!G5="","",'Chiffres clés (brut)'!G5*1000)
A6: 1 | B6: ATLANTIQUE ASSURANCE BENIN VIE | C6: BENIN | D6: Vie | E6: Autres charges de l'exercice | F6: 2022 | G6: =IF('Chiffres clés (brut)'!G6="","",'Chiffres clés (brut)'!G6*1000)
A7: 1 | B7: ATLANTIQUE ASSURANCE BENIN VIE | C7: BENIN | D7: Vie | E7: Autres charges de l'exercice | F7: 2023 | G7: =IF('Chiffres clés (brut)'!G7="","",'Chiffres clés (brut)'!G7*1000)
A8: 1 | B8: ATLANTIQUE ASSURANCE BENIN VIE | C8: BENIN | D8: Vie | E8: Provisions mathématiques (clôture) | F8: 2022 | G8: =IF('Chiffres clés (brut)'!G8="","",'Chiffres clés (brut)'!G8*1000)
A9: 1 | B9: ATLANTIQUE ASSURANCE BENIN VIE | C9: BENIN | D9: Vie | E9: Provisions mathématiques (clôture) | F9: 2023 | G9: =IF('Chiffres clés (brut)'!G9="","",'Chiffres clés (brut)'!G9*1000)
A10: 1 | B10: ATLANTIQUE ASSURANCE BENIN VIE | C10: BENIN | D10: Vie | E10: Provisions mathématiques (ouverture) | F10: 2022 | G10: =IF('Chiffres clés (brut)'!G10="","",'Chiffres clés (brut)'!G10*1000)
A11: 1 | B11: ATLANTIQUE ASSURANCE BENIN VIE | C11: BENIN | D11: Vie | E11: Provisions mathématiques (ouverture) | F11: 2023 | G11: =IF('Chiffres clés (brut)'!G11="","",'Chiffres clés (brut)'!G11*1000)
A12: 1 | B12: ATLANTIQUE ASSURANCE BENIN VIE | C12: BENIN | D12: Vie | E12: Primes cédées aux réassureurs | F12: 2022 | G12: =IF('Chiffres clés (brut)'!G12="","",'Chiffres clés (brut)'!G12*1000)
A13: 1 | B13: ATLANTIQUE ASSURANCE BENIN VIE | C13: BENIN | D13: Vie | E13: Primes cédées aux réassureurs | F13: 2023 | G13: =IF('Chiffres clés (brut)'!G13="","",'Chiffres clés (brut)'!G13*1000)
... A3569: 117 | B3569: SUNU ASSURANCES IARD - TOGO | C3569: TOGO | D3569: Non-vie | E3569: Dont liquidités | F3569: 2023 | G3569: =IF('Chiffres clés (brut)'!G3569="","",'Chiffres clés (brut)'!G3569*1000)

Sheet Identification (brut)
A1: No enregistrement | B1: Societe | C1: Pays | D1: Branche | E1: Directeur general | F1: Date de creation | G1: Capital social (F CFA) | H1: Cadres | I1: Maitrise | J1: Employes | K1: Annee N | L1: Date d'import
A2: 1 | B2: ATLANTIQUE ASSURANCE BENIN VIE | C2: BENIN | D2: Vie | E2: Corinne GBENOU FOURN | F2: 34662 | G2: 3299350000 | H2: 9 | I2: 6 | J2: 2 | K2: 2023 | L2: 46290.674
A3: 2 | B3: CIF ASSURANCES VIE | C3: BENIN | D3: Vie | E3: Félix Edouard LADEKAN | F3: 41261 | G3: 1249280000 | H3: 11 | I3: 2 | J3: 2 | K3: 2023 | L3: 46290.674
A4: 3 | B4: L'AFRICAINE VIE BENIN | C4: BENIN | D4: Vie | E4: Hervé TCHIAKPE | F4: 38821 | G4: 3000000000 | H4: 10 | I4: 17 | J4: 2 | K4: 2023 | L4: 46290.674
A5: 4 | B5: NOUVELLE SOCIETE INTERAFRICAINE D'ASSURANCES VIE | C5: BENIN | D5: Vie | E5: DOSSOU FREJUS LIDWIN | F5: 38457 | G5: 3000000000 | H5: 14 | I5: 9 | J5: 2 | K5: 2023 | L5: 46290.674
A6: 5 | B6: SANLAM ASSURANCE VIE | C6: BENIN | D6: Vie | E6: Mariam NASSIROU | F6: 35230 | G6: 3000000000 | H6: 16 | I6: 49 | J6: 0 | K6: 2023 | L6: 46290.674
A7: 6 | B7: SUNU ASSURANCES VIE BENIN | C7: BENIN | D7: Vie | E7: Souleymane Wassila FAYE | F7: 34655 | G7: 3000000000 | H7: 37 | I7: 6 | J7: 1 | K7: 2023 | L7: 46290.674
A8: 7 | B8: ATLANTIQUE ASSURANCES BENIN IARDT | C8: BENIN | D8: Non-vie | E8: AYIVI-ELEGBEDE Florence | F8: 42459 | G8: 5000000000 | H8: 21 | I8: 23 | J8: 4 | K8: 2023 | L8: 46290.674
A9: 8 | B9: L'AFRICAINE DES ASSURANCES | C9: BENIN | D9: Non-vie | E9: Kenneth ELEGBEDE | F9: 35739 | G9: 4493470000 | H9: 29 | I9: 48 | J9: 7 | K9: 2023 | L9: 46290.674
A10: 9 | B10: LA GENERALE DES ASSURANCES | C10: BENIN | D10: Non-vie | E10: Gaston Arnaud de SOUZA | F10: 36280 | G10: 3000000000 | H10: 7 | I10: 9 | J10: 9 | K10: 2023 | L10: 46290.674
A11: 10 | B11: NOBILA ASSURANCES SA | C11: BENIN | D11: Non-vie | E11: André A. AZIBLI | F11: 38630 | G11: 3000000000 | H11: 9 | I11: 8 | J11: 11 | K11: 2023 | L11: 46290.674
A12: 11 | B12: NOUVELLE SOCIETE INTERAFRICAINE D'ASSURANCES | C12: BENIN | D12: Non-vie | E12: AGBOTA Fabrice | F12: 35796 | G12: 4800000000 | H12: 27 | I12: 25 | J12: 4 | K12: 2023 | L12: 46290.674
A13: 12 | B13: SANLAM ASSURANCE | C13: BENIN | D13: Non-vie | E13: Edmond DOSSOU | F13: 40420 | G13: 3000000000 | H13: 12 | I13: 22 | J13: 2 | K13: 2023 | L13: 46290.674
... A48: 47 | B48: ALLIANZ CÔTE D'IVOIRE ASSURANCES | C48: COTE D'IVOIRE | D48: Non-vie | E48: Mamadou G. K. KONE | F48: 27760 | G48: 3000000000 | H48: 55 | I48: 49 | J48: 2 | K48: 2023 | L48: 46290.674
A49: 48 | B49: AMSA ASSURANCES | C49: COTE D'IVOIRE | D49: Non-vie | E49: Yatassaye SAMBA | F49: En 1972 | G49: 5000000000 | H49: 43 | I49: 49 | J49: 3 | K49: 2023 | L49: 46290.674
A50: 49 | B50: ASSURANCES COMAR Côte d’Ivoire (COMAR-CI) | C50: COTE D'IVOIRE | D50: Non-vie | E50: Théophile MBORO ASSOGHO | F50: 42681 | G50: 8747780000 | H50: 20 | I50: 23 | J50: 4 | K50: 2023 | L50: 46290.674
A51: 50 | B51: ATLANTIQUE ASSURANCES COTE D'IVOIRE (AACI) | C51: COTE D'IVOIRE | D51: Non-vie | E51: Estelle TRAORE | F51: 1956 | G51: 3000000000 | H51: 45 | I51: 29 | J51: 7 | K51: 2023 | L51: 46290.674
A52: 51 | B52: AXA ASSURANCES | C52: COTE D'IVOIRE | D52: Non-vie | E52: Téyi LAWSON | F52: 29587 | G52: 5000006000 | H52: 34 | I52: 30 | J52: 0 | K52: 2023 | L52: 46290.674
A53: 52 | B53: LA LOYALE ASSURANCES | C53: COTE D'IVOIRE | D53: Non-vie | E53: BROU Yvette Mamy Koko | F53: 37926 | G53: 3486932497 | H53: 16 | I53: 20 | J53: 11 | K53: 2023 | L53: 46290.674
A54: 53 | B54: NOUVELLE SOCIETE INTERAFRICAINE D'ASSURANCES | C54: COTE D'IVOIRE | D54: Non-vie | E54: Magloire DOCHAMOU | F54: 34851 | G54: 7600000000 | H54: 78 | I54: 39 | J54: 3 | K54: 2023 | L54: 46290.674
A55: 54 | B55: SANLAM ASSURANCE CÔTE D'IVOIRE | C55: COTE D'IVOIRE | D55: Non-vie | E55: OUEDRAOGO Roland Zwewendpaogre | F55: 29252 | G55: 5000000000 | H55: 68 | I55: 54 | J55: 29 | K55: 2023 | L55: 46290.674
A56: 55 | B56: SERENITY ASSURANCES SA | C56: COTE D'IVOIRE | D56: Non-vie | E56: Maurice KIPPRE DIGBEU | F56: 39554 | G56: 3000000000 | H56: 24 | I56: 60 | J56: 23 | K56: 2023 | L56: 46290.674
A57: 56 | B57: SONAM GENERALE ASSURANCES COTE D'IVOIRE | C57: COTE D'IVOIRE | D57: Non-vie | E57: Papa Ibra DIENA | F57: 1987 | G57: 500000000 | H57: 14 | I57: 37 | J57: 14 | K57: 2023 | L57: 46290.674
A58: 57 | B58: SUNU ASSURANCES IARD | C58: COTE D'IVOIRE | D58: Non-vie | E58: Mamadou Moussa DIOUF | F58: 35529 | G58: 5000000000 | H58: 39 | I58: 27 | J58: 0 | K58: 2023 | L58: 46290.674
A59: 58 | B59: ASSURANCES INDUSTRIELLES ET COMMERCIALES SA | C59: GABON | D59: Non-vie | E59: Stephen MOUSSIROU | F59: 35431 | G59: 6000000000 | H59: 33 | I59: 28 | J59: 11 | K59: 2023 | L59: 46290.674
A60: 59 | B60: AXA ASSURANCES | C60: GABON | D60: Non-vie | E60: Marielle BAYE | F60: 27760 | G60: 5022465000 | H60: 24 | I60: 32 | J60: 18 | K60: 2023 | L60: 46290.674
A61: 60 | B61: CIF ASSURANCES-VIE MALI | C61: MALI | D61: Vie | E61: Corneille SANON | F61: 43096 | G61: 1167340000 | H61: 7 | I61: 1 | J61: 1 | K61: 2023 | L61: 46290.674
A62: 61 | B62: NSIA VIE MALI | C62: MALI | D62: Vie | E62: Lamine COULIBALY | F62: 39961 | G62: 7745170000 | H62: 3 | I62: 18 | J62: 2 | K62: 2023 | L62: 46290.674
A63: 62 | B63: SANLAM ASSURANCE VIE MALI | C63: MALI | D63: Vie | E63: Bikiry MAKANGUILE | F63: 40716 | G63: 3000000000 | H63: 7 | I63: 9 | J63: 14 | K63: 2023 | L63: 46290.674
A64: 63 | B64: SOCIETE NOUVELLE D'ASSURANCE VIE (SONAVIE) | C64: MALI | D64: Vie | E64: Adama DIALLO | F64: 35247 | G64: 5158990000 | H64: 15 | I64: 0 | J64: 22 | K64: 2023 | L64: 46290.674
A65: 64 | B65: AFG ASSURANCES MALI IARD | C65: MALI | D65: Non-vie | E65: CISSE Adam BA | F65: 41997 | G65: 3000000000 | H65: 8 | I65: 23 | J65: 14 | K65: 2023 | L65: 46290.674
A66: 65 | B66: ASSURANCES LAFIA SA | C66: MALI | D66: Non-vie | E66: Kadiatou KONE | F66: 30523 | G66: 3000000000 | H66: 14 | I66: 5 | J66: 14 | K66: 2023 | L66: 46290.674
A67: 66 | B67: COMPAGNIE D'ASSURANCE ET REASSURANCE SABU NYUMAN | C67: MALI | D67: Non-vie | E67: Abdrahamane KOUYATE | F67: 30772 | G67: 4379560000 | H67: 5 | I67: 21 | J67: 18 | K67: 2023 | L67: 46290.674
A68: 67 | B68: LES ASSURANCES BLEUES CNAR | C68: MALI | D68: Non-vie | E68: SANOGO Karim | F68: 25239 | G68: 3383897675 | H68: 13 | I68: 11 | J68: 14 | K68: 2023 | L68: 46290.674
A69: 68 | B69: NOUVELLE ALLIANCE D'ASSURANCES SA | C69: MALI | D69: Non-vie | E69: Abdoulaye TOURE | F69: 39133 | G69: 3000000000 | H69: 2 | I69: 8 | J69: 9 | K69: 2023 | L69: 46290.674
... A86: 85 | B86: SAAR VIE SENEGAL | C86: SENEGAL | D86: Vie | E86: BOPDA FONKO Cyrille | F86: 34074 | G86: 5000000000 | H86: 6 | I86: 4 | J86: 0 | K86: 2023 | L86: 46290.674
A87: 86 | B87: SONAM ASSURANCES VIE | C87: SENEGAL | D87: Vie | E87: Souleymane NIANE | F87: 25/09/20212 | G87: 3000000000 | H87: 12 | I87: 17 | J87: 18 | K87: 2023 | L87: 46290.674
A88: 87 | B88: SUNU ASSURANCES VIE SENEGAL | C88: SENEGAL | D88: Vie | E88: SY Adjaratou Khady NDAO | F88: 31658 | G88: 3000000000 | H88: 6 | I88: 30 | J88: 0 | K88: 2023 | L88: 46290.674
A89: 88 | B89: WAFA ASSURANCE VIE | C89: SENEGAL | D89: Vie | E89: Chakib HASSAN | F89: 41894 | G89: 3000000000 | H89: 11 | I89: 19 | J89: 0 | K89: 2023 | L89: 46290.674
A90: 89 | B90: ALLIANZ SENEGAL ASSURANCES | C90: SENEGAL | D90: Non-vie | E90: Alphonsine DASILVA | F90: 32121 | G90: 3000000000 | H90: 29 | I90: 28 | J90: 4 | K90: 2023 | L90: 46290.674
...

Sheet Emission&Prestations (brut)
A1: No enregistrement | B1: Societe | C1: Pays | D1: Branche | E1: Bloc | F1: Categorie | G1: Rubrique | H1: Mesure | I1: Annee | J1: Valeur (milliers F CFA) | K1: Cellule source
A2: 1 | B2: ATLANTIQUE ASSURANCE BENIN VIE | C2: BENIN | D2: Vie | E2: Emissions | F2: Individuelles | G2: Contrats en cas de vie | H2: Emissions nettes | I2: 2022 | J2: 0 | K2: PDF p. 15 (page imprimee 10)
A3: 1 | B3: ATLANTIQUE ASSURANCE BENIN VIE | C3: BENIN | D3: Vie | E3: Emissions | F3: Individuelles | G3: Contrats en cas de vie | H3: Emissions nettes | I3: 2023 | J3: 0 | K3: PDF p. 15 (page imprimee 10)
A4: 1 | B4: ATLANTIQUE ASSURANCE BENIN VIE | C4: BENIN | D4: Vie | E4: Emissions | F4: Individuelles | G4: Contrat en cas de décès | H4: Emissions nettes | I4: 2022 | J4: 565876 | K4: PDF p. 15 (page imprimee 10)
A5: 1 | B5: ATLANTIQUE ASSURANCE BENIN VIE | C5: BENIN | D5: Vie | E5: Emissions | F5: Individuelles | G5: Contrat en cas de décès | H5: Emissions nettes | I5: 2023 | J5: 1177646 | K5: PDF p. 15 (page imprimee 10)
A6: 1 | B6: ATLANTIQUE ASSURANCE BENIN VIE | C6: BENIN | D6: Vie | E6: Emissions | F6: Individuelles | G6: Mixte | H6: Emissions nettes | I6: 2022 | J6: 938229 | K6: PDF p. 15 (page imprimee 10)
A7: 1 | B7: ATLANTIQUE ASSURANCE BENIN VIE | C7: BENIN | D7: Vie | E7: Emissions | F7: Individuelles | G7: Mixte | H7: Emissions nettes | I7: 2023 | J7: 782690 | K7: PDF p. 15 (page imprimee 10)
A8: 1 | B8: ATLANTIQUE ASSURANCE BENIN VIE | C8: BENIN | D8: Vie | E8: Emissions | F8: Individuelles | G8: Epargne | H8: Emissions nettes | I8: 2022 | J8: 613008 | K8: PDF p. 15 (page imprimee 10)
A9: 1 | B9: ATLANTIQUE ASSURANCE BENIN VIE | C9: BENIN | D9: Vie | E9: Emissions | F9: Individuelles | G9: Epargne | H9: Emissions nettes | I9: 2023 | J9: 453206 | K9: PDF p. 15 (page imprimee 10)
A10: 1 | B10: ATLANTIQUE ASSURANCE BENIN VIE | C10: BENIN | D10: Vie | E10: Emissions | F10: Individuelles | G10: Titre de capitalisation | H10: Emissions nettes | I10: 2022 | J10: 0 | K10: PDF p. 15 (page imprimee 10)
A11: 1 | B11: ATLANTIQUE ASSURANCE BENIN VIE | C11: BENIN | D11: Vie | E11: Emissions | F11: Individuelles | G11: Titre de capitalisation | H11: Emissions nettes | I11: 2023 | J11: 0 | K11: PDF p. 15 (page imprimee 10)
A12: 1 | B12: ATLANTIQUE ASSURANCE BENIN VIE | C12: BENIN | D12: Vie | E12: Emissions | F12: Individuelles | G12: Complémentaires | H12: Emissions nettes | I12: 2022 | J12: 50737 | K12: PDF p. 15 (page imprimee 10)
A13: 1 | B13: ATLANTIQUE ASSURANCE BENIN VIE | C13: BENIN | D13: Vie | E13: Emissions | F13: Individuelles | G13: Complémentaires | H13: Emissions nettes | I13: 2023 | J13: 35565 | K13: PDF p. 15 (page imprimee 10)
... A78: 2 | B78: CIF ASSURANCES VIE | C78: BENIN | D78: Vie | E78: Emissions | F78: Acceptations | G78: Acceptations | H78: Emissions nettes | I78: 2022 | J78: 0 | K78: PDF p. 16 (page imprimee 11)
A79: 2 | B79: CIF ASSURANCES VIE | C79: BENIN | D79: Vie | E79: Emissions | F79: Acceptations | G79: Acceptations | H79: Emissions nettes | I79: 2023 | K79: PDF p. 16 (page imprimee 11)
A80: 2 | B80: CIF ASSURANCES VIE | C80: BENIN | D80: Vie | E80: Prestations | F80: Individuelles | G80: Contrats en cas de vie | H80: Prestations versees | I80: 2022 | J80: 0 | K80: PDF p. 16 (page imprimee 11)
A81: 2 | B81: CIF ASSURANCES VIE | C81: BENIN | D81: Vie | E81: Prestations | F81: Individuelles | G81: Contrats en cas de vie | H81: Prestations versees | I81: 2023 | J81: 0 | K81: PDF p. 16 (page imprimee 11)
A82: 2 | B82: CIF ASSURANCES VIE | C82: BENIN | D82: Vie | E82: Prestations | F82: Individuelles | G82: Contrat en cas de décès | H82: Prestations versees | I82: 2022 | J82: 290759 | K82: PDF p. 16 (page imprimee 11)
A83: 2 | B83: CIF ASSURANCES VIE | C83: BENIN | D83: Vie | E83: Prestations | F83: Individuelles | G83: Contrat en cas de décès | H83: Prestations versees | I83: 2023 | J83: 267423 | K83: PDF p. 16 (page imprimee 11)
A84: 2 | B84: CIF ASSURANCES VIE | C84: BENIN | D84: Vie | E84: Prestations | F84: Individuelles | G84: Mixte | H84: Prestations versees | I84: 2022 | J84: 0 | K84: PDF p. 16 (page imprimee 11)
A85: 2 | B85: CIF ASSURANCES VIE | C85: BENIN | D85: Vie | E85: Prestations | F85: Individuelles | G85: Mixte | H85: Prestations versees | I85: 2023 | J85: 0 | K85: PDF p. 16 (page imprimee 11)
A86: 2 | B86: CIF ASSURANCES VIE | C86: BENIN | D86: Vie | E86: Prestations | F86: Individuelles | G86: Epargne | H86: Prestations versees | I86: 2022 | J86: 139050 | K86: PDF p. 16 (page imprimee 11)
A87: 2 | B87: CIF ASSURANCES VIE | C87: BENIN | D87: Vie | E87: Prestations | F87: Individuelles | G87: Epargne | H87: Prestations versees | I87: 2023 | J87: 126867 | K87: PDF p. 16 (page imprimee 11)
A88: 2 | B88: CIF ASSURANCES VIE | C88: BENIN | D88: Vie | E88: Prestations | F88: Individuelles | G88: Titre de capitalisation | H88: Prestations versees | I88: 2022 | J88: 0 | K88: PDF p. 16 (page imprimee 11)
A89: 2 | B89: CIF ASSURANCES VIE | C89: BENIN | D89: Vie | E89: Prestations | F89: Individuelles | G89: Titre de capitalisation | H89: Prestations versees | I89: 2023 | J89: 0 | K89: PDF p. 16 (page imprimee 11)
A90: 2 | B90: CIF ASSURANCES VIE | C90: BENIN | D90: Vie | E90: Prestations | F90: Individuelles | G90: Complémentaires | H90: Prestations versees | I90: 2022 | J90: 0 | K90: PDF p. 16 (page imprimee 11)
A91: 2 | B91: CIF ASSURANCES VIE | C91: BENIN | D91: Vie | E91: Prestations | F91: Individuelles | G91: Complémentaires | H91: Prestations versees | I91: 2023 | J91: 0 | K91: PDF p. 16 (page imprimee 11)
... A1000: 18 | B1000: GENERALE DES ASSURANCES | C1000: BURKINA FASO | D1000: Non-vie | E1000: Sinistralite | F1000: Acceptations | G1000: Acceptations | H1000: Charges de sinistres (CS) | I1000: 2022 | J1000: 0 | K1000: PDF p. 37 (page imprimee 32)
A1001: 18 | B1001: GENERALE DES ASSURANCES | C1001: BURKINA FASO | D1001: Non-vie | E1001: Sinistralite | F1001: Acceptations | G1001: Acceptations | H1001: Charges de sinistres (CS) | I1001: 2023 | K1001: PDF p. 37 (page imprimee 32)
A1002: 19 | B1002: RAYNAL ASSURANCES IARD | C1002: BURKINA FASO | D1002: Non-vie | E1002: Emissions | F1002: Affaires directes | G1002: Accidents corporels et maladie | H1002: Primes émises | I1002: 2022 | J1002: 1289545 | K1002: PDF p. 38 (page imprimee 33)
A1003: 19 | B1003: RAYNAL ASSURANCES IARD | C1003: BURKINA FASO | D1003: Non-vie | E1003: Emissions | F1003: Affaires directes | G1003: Accidents corporels et maladie | H1003: Primes acquises (PA) | I1003: 2022 | J1003: 1530348 | K1003: PDF p. 38 (page imprimee 33)
A1004: 19 | B1004: RAYNAL ASSURANCES IARD | C1004: BURKINA FASO | D1004: Non-vie | E1004: Emissions | F1004: Affaires directes | G1004: Accidents corporels et maladie | H1004: Primes émises | I1004: 2023 | J1004: 1489879 | K1004: PDF p. 38 (page imprimee 33)
A1005: 19 | B1005: RAYNAL ASSURANCES IARD | C1005: BURKINA FASO | D1005: Non-vie | E1005: Emissions | F1005: Affaires directes | G1005: Accidents corporels et maladie | H1005: Primes acquises (PA) | I1005: 2023 | J1005: 1525722 | K1005: PDF p. 38 (page imprimee 33)
A1006: 19 | B1006: RAYNAL ASSURANCES IARD | C1006: BURKINA FASO | D1006: Non-vie | E1006: Emissions | F1006: Affaires directes | G1006: Automobile : Responsabilité Civile | H1006: Primes émises | I1006: 2022 | J1006: 1748038 | K1006: PDF p. 38 (page imprimee 33)
A1007: 19 | B1007: RAYNAL ASSURANCES IARD | C1007: BURKINA FASO | D1007: Non-vie | E1007: Emissions | F1007: Affaires directes | G1007: Automobile : Responsabilité Civile | H1007: Primes acquises (PA) | I1007: 2022 | J1007: 1735265 | K1007: PDF p. 38 (page imprimee 33)
A1008: 19 | B1008: RAYNAL ASSURANCES IARD | C1008: BURKINA FASO | D1008: Non-vie | E1008: Emissions | F1008: Affaires directes | G1008: Automobile : Responsabilité Civile | H1008: Primes émises | I1008: 2023 | J1008: 1760841 | K1008: PDF p. 38 (page imprimee 33)
A1009: 19 | B1009: RAYNAL ASSURANCES IARD | C1009: BURKINA FASO | D1009: Non-vie | E1009: Emissions | F1009: Affaires directes | G1009: Automobile : Responsabilité Civile | H1009: Primes acquises (PA) | I1009: 2023 | J1009: 1791382 | K1009: PDF p. 38 (page imprimee 33)
A1010: 19 | B1010: RAYNAL ASSURANCES IARD | C1010: BURKINA FASO | D1010: Non-vie | E1010: Emissions | F1010: Affaires directes | G1010: Automobile : Autres risques | H1010: Primes émises | I1010: 2022 | J1010: 1553129 | K1010: PDF p. 38 (page imprimee 33)
A1011: 19 | B1011: RAYNAL ASSURANCES IARD | C1011: BURKINA FASO | D1011: Non-vie | E1011: Emissions | F1011: Affaires directes | G1011: Automobile : Autres risques | H1011: Primes acquises (PA) | I1011: 2022 | J1011: 1589873 | K1011: PDF p. 38 (page imprimee 33)
A1012: 19 | B1012: RAYNAL ASSURANCES IARD | C1012: BURKINA FASO | D1012: Non-vie | E1012: Emissions | F1012: Affaires directes | G1012: Automobile : Autres risques | H1012: Primes émises | I1012: 2023 | J1012: 1670331 | K1012: PDF p. 38 (page imprimee 33)
...

Sheet Chiffres clés (brut)
A1: No enregistrement | B1: Societe | C1: Pays | D1: Branche | E1: Rubrique | F1: Annee | G1: Valeur (milliers F CFA) | H1: Cellule source
A2: 1 | B2: ATLANTIQUE ASSURANCE BENIN VIE | C2: BENIN | D2: Vie | E2: Produits financiers nets | F2: 2022 | G2: 280781 | H2: PDF p. 15 (page imprimee 10)
A3: 1 | B3: ATLANTIQUE ASSURANCE BENIN VIE | C3: BENIN | D3: Vie | E3: Produits financiers nets | F3: 2023 | G3: 263564 | H3: PDF p. 15 (page imprimee 10)
A4: 1 | B4: ATLANTIQUE ASSURANCE BENIN VIE | C4: BENIN | D4: Vie | E4: Commissions | F4: 2022 | G4: 203777 | H4: PDF p. 15 (page imprimee 10)
A5: 1 | B5: ATLANTIQUE ASSURANCE BENIN VIE | C5: BENIN | D5: Vie | E5: Commissions | F5: 2023 | G5: 322156 | H5: PDF p. 15 (page imprimee 10)
A6: 1 | B6: ATLANTIQUE ASSURANCE BENIN VIE | C6: BENIN | D6: Vie | E6: Autres charges de l'exercice | F6: 2022 | G6: 1155007 | H6: PDF p. 15 (page imprimee 10)
A7: 1 | B7: ATLANTIQUE ASSURANCE BENIN VIE | C7: BENIN | D7: Vie | E7: Autres charges de l'exercice | F7: 2023 | G7: 1547992 | H7: PDF p. 15 (page imprimee 10)
A8: 1 | B8: ATLANTIQUE ASSURANCE BENIN VIE | C8: BENIN | D8: Vie | E8: Provisions mathématiques (clôture) | F8: 2022 | G8: 6983688 | H8: PDF p. 15 (page imprimee 10)
A9: 1 | B9: ATLANTIQUE ASSURANCE BENIN VIE | C9: BENIN | D9: Vie | E9: Provisions mathématiques (clôture) | F9: 2023 | G9: 7529625 | H9: PDF p. 15 (page imprimee 10)
A10: 1 | B10: ATLANTIQUE ASSURANCE BENIN VIE | C10: BENIN | D10: Vie | E10: Provisions mathématiques (ouverture) | F10: 2022 | G10: 6015491 | H10: PDF p. 15 (page imprimee 10)
A11: 1 | B11: ATLANTIQUE ASSURANCE BENIN VIE | C11: BENIN | D11: Vie | E11: Provisions mathématiques (ouverture) | F11: 2023 | G11: 6983688 | H11: PDF p. 15 (page imprimee 10)
A12: 1 | B12: ATLANTIQUE ASSURANCE BENIN VIE | C12: BENIN | D12: Vie | E12: Primes cédées aux réassureurs | F12: 2022 | G12: 48176 | H12: PDF p. 15 (page imprimee 10)
A13: 1 | B13: ATLANTIQUE ASSURANCE BENIN VIE | C13: BENIN | D13: Vie | E13: Primes cédées aux réassureurs | F13: 2023 | G13: 40020 | H13: PDF p. 15 (page imprimee 10)
... A773: 26 | B773: SUNU ASSURANCES VIE CAMEROUN | C773: CAMEROUN | D773: Vie | E773: Dont liquidités | F773: 2023 | G773: 24893707 | H773: PDF p. 47 (page imprimee 42)
A774: 27 | B774: WAFA ASSURANCE VIE CAMEROUN | C774: CAMEROUN | D774: Vie | E774: Produits financiers nets | F774: 2022 | H774: PDF p. 48 (page imprimee 43)
A775: 27 | B775: WAFA ASSURANCE VIE CAMEROUN | C775: CAMEROUN | D775: Vie | E775: Produits financiers nets | F775: 2023 | G775: 1121847 | H775: PDF p. 48 (page imprimee 43)
A776: 27 | B776: WAFA ASSURANCE VIE CAMEROUN | C776: CAMEROUN | D776: Vie | E776: Commissions | F776: 2022 | H776: PDF p. 48 (page imprimee 43)
A777: 27 | B777: WAFA ASSURANCE VIE CAMEROUN | C777: CAMEROUN | D777: Vie | E777: Commissions | F777: 2023 | G777: 516396 | H777: PDF p. 48 (page imprimee 43)
A778: 27 | B778: WAFA ASSURANCE VIE CAMEROUN | C778: CAMEROUN | D778: Vie | E778: Autres charges de l'exercice | F778: 2022 | H778: PDF p. 48 (page imprimee 43)
A779: 27 | B779: WAFA ASSURANCE VIE CAMEROUN | C779: CAMEROUN | D779: Vie | E779: Autres charges de l'exercice | F779: 2023 | G779: 1377252 | H779: PDF p. 48 (page imprimee 43)
A780: 27 | B780: WAFA ASSURANCE VIE CAMEROUN | C780: CAMEROUN | D780: Vie | E780: Provisions mathématiques (clôture) | F780: 2022 | H780: PDF p. 48 (page imprimee 43)
A781: 27 | B781: WAFA ASSURANCE VIE CAMEROUN | C781: CAMEROUN | D781: Vie | E781: Provisions mathématiques (clôture) | F781: 2023 | G781: 20405099 | H781: PDF p. 48 (page imprimee 43)
A782: 27 | B782: WAFA ASSURANCE VIE CAMEROUN | C782: CAMEROUN | D782: Vie | E782: Provisions mathématiques (ouverture) | F782: 2022 | H782: PDF p. 48 (page imprimee 43)
A783: 27 | B783: WAFA ASSURANCE VIE CAMEROUN | C783: CAMEROUN | D783: Vie | E783: Provisions mathématiques (ouverture) | F783: 2023 | G783: 20405099 | H783: PDF p. 48 (page imprimee 43)
A784: 27 | B784: WAFA ASSURANCE VIE CAMEROUN | C784: CAMEROUN | D784: Vie | E784: Primes cédées aux réassureurs | F784: 2022 | H784: PDF p. 48 (page imprimee 43)
A785: 27 | B785: WAFA ASSURANCE VIE CAMEROUN | C785: CAMEROUN | D785: Vie | E785: Primes cédées aux réassureurs | F785: 2023 | G785: 96485 | H785: PDF p. 48 (page imprimee 43)
A786: 27 | B786: WAFA ASSURANCE VIE CAMEROUN | C786: CAMEROUN | D786: Vie | E786: Part des réassureurs dans les charges | F786: 2022 | H786: PDF p. 48 (page imprimee 43)
A787: 27 | B787: WAFA ASSURANCE VIE CAMEROUN | C787: CAMEROUN | D787: Vie | E787: Part des réassureurs dans les charges | F787: 2023 | G787: 9234 | H787: PDF p. 48 (page imprimee 43)
A788: 27 | B788: WAFA ASSURANCE VIE CAMEROUN | C788: CAMEROUN | D788: Vie | E788: Résultats d’exploitations nets | F788: 2022 | H788: PDF p. 48 (page imprimee 43)
A789: 27 | B789: WAFA ASSURANCE VIE CAMEROUN | C789: CAMEROUN | D789: Vie | E789: Résultats d’exploitations nets | F789: 2023 | G789: 358425 | H789: PDF p. 48 (page imprimee 43)
A790: 27 | B790: WAFA ASSURANCE VIE CAMEROUN | C790: CAMEROUN | D790: Vie | E790: Total des capitaux propres et réserves | F790: 2022 | H790: PDF p. 48 (page imprimee 43)
A791: 27 | B791: WAFA ASSURANCE VIE CAMEROUN | C791: CAMEROUN | D791: Vie | E791: Total des capitaux propres et réserves | F791: 2023 | G791: 5134551 | H791: PDF p. 48 (page imprimee 43)
A792: 27 | B792: WAFA ASSURANCE VIE CAMEROUN | C792: CAMEROUN | D792: Vie | E792: Marge réglementaire | F792: 2022 | H792: PDF p. 48 (page imprimee 43)
A793: 27 | B793: WAFA ASSURANCE VIE CAMEROUN | C793: CAMEROUN | D793: Vie | E793: Marge réglementaire | F793: 2023 | G793: 939760 | H793: PDF p. 48 (page imprimee 43)
A794: 27 | B794: WAFA ASSURANCE VIE CAMEROUN | C794: CAMEROUN | D794: Vie | E794: Marge disponible | F794: 2022 | H794: PDF p. 48 (page imprimee 43)
A795: 27 | B795: WAFA ASSURANCE VIE CAMEROUN | C795: CAMEROUN | D795: Vie | E795: Marge disponible | F795: 2023 | G795: 5322708 | H795: PDF p. 48 (page imprimee 43)
A796: 27 | B796: WAFA ASSURANCE VIE CAMEROUN | C796: CAMEROUN | D796: Vie | E796: Engagements Réglementés | F796: 2022 | H796: PDF p. 48 (page imprimee 43)
A797: 27 | B797: WAFA ASSURANCE VIE CAMEROUN | C797: CAMEROUN | D797: Vie | E797: Engagements Réglementés | F797: 2023 | G797: 20894700 | H797: PDF p. 48 (page imprimee 43)
A798: 27 | B798: WAFA ASSURANCE VIE CAMEROUN | C798: CAMEROUN | D798: Vie | E798: Actifs admis | F798: 2022 | H798: PDF p. 48 (page imprimee 43)
A799: 27 | B799: WAFA ASSURANCE VIE CAMEROUN | C799: CAMEROUN | D799: Vie | E799: Actifs admis | F799: 2023 | G799: 24666274 | H799: PDF p. 48 (page imprimee 43)
...
